Workbook

Sheet Read Me
A1: Addition Ballpark Template — DRAFT for review
A2: Deitemeyer Brothers · General Construction · drafted 27 Sep 2026 · decisions applied 28 Sep 2026
A4: What this is
A5: The build sheet for a formula-driven addition ballpark in JobTread, plus a working calculator so the numbers can be checked before anything is built.
A6: It prices a room addition, sunroom or detached garage at Good / Better / Best from 28 site-visit measurements, using DB's catalog rates and markup. It runs on the same engine as the bathroom and kitchen templates.
A7: A bathroom or kitchen inside the addition is priced by that room's own template on the same job. This template prices only the plumbing rough-in to reach it.
A9: How to use it
A10: 1. Calculator tab: type the site-visit numbers into the yellow cells. The three totals and ranges update.
A11: 2. Template tab: every JobTread line with its cost group, cost code, unit, exact quantity formula, and unit cost and price per tier.
A12: 3. Parameters tab: the 28 site-visit parameters plus the contingency rate, which the estimator sets. Each starts with 'Addition ' so it never collides with a bath or kitchen on the same job.
A13: 4. Rates tab: markup by cost type, and the ± band. It is set to ±20% for additions.
A14: 5. Calibration tab: how the template compares with DB's addition estimates, total and block by block.
... A32: Source for every rate: DB's catalog and addition estimates, read from JobTread (read-only) on 27 Sep 2026. See Calibration tab.

Sheet Calculator
A1: Addition Ballpark Calculator
A2: Type the site-visit numbers into the yellow cells. Example values below are a 16 x 20 family room on a crawl space with four windows and a patio door, not a real customer.
A4: Site-visit measurement | B4: Value | C4: What to enter | D4: JobTread parameter name | F4: Ballpark | G4: Good | H4: Better | I4: Best
A5: Addition Width | B5: 20 | C5: Feet along the house wall (for a detached building, the front wall) | D5: {Addition Width} | F5: Phase 1 - General Requirements | G5: =SUMIFS(Template!K5:K54,Template!B5:B54,"*Phase 1 -*") -> 7032.5 | H5: =SUMIFS(Template!O5:O54,Template!B5:B54,"*Phase 1 -*") -> 7032.5 | I5: =SUMIFS(Template!S5:S54,Template!B5:B54,"*Phase 1 -*") -> 7032.5
A6: Addition Depth | B6: 16 | C6: Feet out from the house | D6: {Addition Depth} | F6: Phase 2 - Foundation & Framing | G6: =SUMIFS(Template!K5:K54,Template!B5:B54,"*Phase 2 -*") -> 26404.48 | H6: =SUMIFS(Template!O5:O54,Template!B5:B54,"*Phase 2 -*") -> 26404.48 | I6: =SUMIFS(Template!S5:S54,Template!B5:B54,"*Phase 2 -*") -> 26404.48
A7: Addition Stories | B7: 1 | C7: Finished floors on the new footprint: 1 or 2 | D7: {Addition Stories} | F7: Phase 3 - Exterior & Rough-In | G7: =SUMIFS(Template!K5:K54,Template!B5:B54,"*Phase 3 -*") -> 11470.54 | H7: =SUMIFS(Template!O5:O54,Template!B5:B54,"*Phase 3 -*") -> 11470.54 | I7: =SUMIFS(Template!S5:S54,Template!B5:B54,"*Phase 3 -*") -> 11470.54
A8: Addition Wall Height | B8: 8 | C8: Wall height in feet per storey (8 for most rooms; 9–10 for garages) | D8: {Addition Wall Height} | F8: Phase 4 - Interior | G8: =SUMIFS(Template!K5:K54,Template!B5:B54,"*Phase 4 -*") -> 14111.79 | H8: =SUMIFS(Template!O5:O54,Template!B5:B54,"*Phase 4 -*") -> 14111.79 | I8: =SUMIFS(Template!S5:S54,Template!B5:B54,"*Phase 4 -*") -> 14111.79
A9: Addition Detached | B9: 0 | C9: 1 = stand-alone building such as a garage (four new walls, no tie-in); 0 = attached | D9: {Addition Detached} | F9: Finish selections (tier) | G9: =SUM(Template!K55:K60) -> 11237.5 | H9: =SUM(Template!O55:O60) -> 15283 | I9: =SUM(Template!S55:S60) -> 22957.85
A10: Addition Crawl Space | B10: 1 | C10: 1 = new crawl-space foundation. Set exactly one foundation to 1. | D10: {Addition Crawl Space} | F10: Contingency (the Addition Contingency Rate) | G10: =SUM(Template!K61:K63) -> 7025.681 | H10: =SUM(Template!O61:O63) -> 7430.231 | I10: =SUM(Template!S61:S63) -> 8197.716
A11: Addition Slab | B11: 0 | C11: 1 = footed slab with a 6-inch stem wall (garages, slab rooms) | D11: {Addition Slab} | F11: Ballpark total | G11: =SUM(G5:G10) -> 77282.491 | H11: =SUM(H5:H10) -> 81732.541 | I11: =SUM(I5:I10) -> 90174.876
A12: Addition Basement | B12: 0 | C12: 1 = full basement under the addition | D12: {Addition Basement} | F12: Check: equals Template total | G12: =IF(ABS(G11-Template!K64)<0.01,"OK","MISMATCH") -> OK | H12: =IF(ABS(H11-Template!O64)<0.01,"OK","MISMATCH") -> OK | I12: =IF(ABS(I11-Template!S64)<0.01,"OK","MISMATCH") -> OK
A13: Addition Piers | B13: 0 | C13: Posts or piers, for a porch-type addition on piers (count). 0 for any other foundation. | D13: {Addition Piers}
A14: Addition Site Excavation | B14: 0 | C14: 1 = DB digs, grades or trenches (tight access, slope, drainage). 0 = the concrete sub's price covers it. | D14: {Addition Site Excavation} | F14: Budget range shown to customer
A15: Addition Roof Tie-In | B15: 1 | C15: 0 = none (detached); 1 = simple shed or gable against the house; 2 = cross-gable or valley | D15: {Addition Roof Tie-In} | F15: Low | G15: =ROUND(G11*(1-RangePct),-2) -> 61800 | H15: =ROUND(H11*(1-RangePct),-2) -> 65400 | I15: =ROUND(I11*(1-RangePct),-2) -> 72100
A16: Addition Electrical | B16: 1 | C16: 1 = wired: outlets, lights, switches. 0 = shell only. | D16: {Addition Electrical} | F16: High | G16: =ROUND(G11*(1+RangePct),-2) -> 92700 | H16: =ROUND(H11*(1+RangePct),-2) -> 98100 | I16: =ROUND(I11*(1+RangePct),-2) -> 108200
A17: Addition Drywall | B17: 1 | C17: 1 = insulated, drywalled and painted (rooms, finished garages). 0 = shell or three-season porch. | D17: {Addition Drywall}
A18: Addition Living Space | B18: 1 | C18: 1 = finished living space: flooring, trim and more coordination. 0 = garage, porch or shell. | D18: {Addition Living Space} | F18: Totals exclude sales tax and the design agreement fee.
A19: Addition Windows | B19: 4 | C19: New windows in the addition | D19: {Addition Windows} | F19: The ± band is set on the Rates tab.
A20: Addition Exterior Doors | B20: 0 | C20: New entry or service doors | D20: {Addition Exterior Doors}
A21: Addition Patio Doors | B21: 1 | C21: New sliding or hinged patio doors | D21: {Addition Patio Doors}
A22: Addition Garage Doors | B22: 0 | C22: Overhead garage doors | D22: {Addition Garage Doors}
A23: Addition Interior Doors | B23: 0 | C23: Interior doors, including closet and bathroom doors | D23: {Addition Interior Doors}
A24: Addition Wall Openings | B24: 1 | C24: Openings cut into the existing house wall (a doorway or wider, with a header) | D24: {Addition Wall Openings}
A25: Addition Plumbing Fixtures | B25: 0 | C25: Fixtures that need new drain and supply run into the addition. Their finish is priced by the bath or kitchen template. | D25: {Addition Plumbing Fixtures}
A26: Addition HVAC Extend | B26: 1 | C26: 1 = extend the existing ductwork into the addition | D26: {Addition HVAC Extend}
A27: Addition HVAC New Unit | B27: 0 | C27: 1 = new mini-split or dedicated system for the addition | D27: {Addition HVAC New Unit}
A28: Addition Extra Siding Squares | B28: 0 | C28: Squares of the house's own siding to replace so it matches (100 SF = 1 square) | D28: {Addition Extra Siding Squares}
A29: Addition Structure Removed | B29: 0 | C29: SF of existing porch, deck, sunroom or room torn down first | D29: {Addition Structure Removed}
A30: Addition Utility Trench | B30: 0 | C30: Feet of trench to feed power to a detached building | D30: {Addition Utility Trench}
A31: Addition Dumpster Loads | B31: 1 | C31: Haul-away loads (1 for most additions; 2–3 with a tear-down) | D31: {Addition Dumpster Loads}
... A34: Addition Permit Fee | B34: 200 | C34: Permit fee DB pays the city or township, in dollars (cost), from the permit table on the Rates tab. The estimator sets it from the job address. | D34: {Addition Permit Fee}

Sheet Template
A1: JobTread build sheet: cost group "BALLPARK — Addition"
A2: One row per JobTread line. Paste the quantity formula exactly as written into the catalog item. Rows marked [each tier] become one item in each of the Good, Better and Best option groups, at that tier's cost. Rows marked with a single tier go only in that option. All other rows are common scope.
A4: # | B4: JobTread cost group path | C4: Line item | D4: Cost code | E4: Unit | F4: JobTread quantity formula | G4: Qty (live) | H4: Good cost | I4: Good type | J4: Good unit price | K4: Good total | L4: Better cost | M4: Better type | N4: Better unit price | O4: Better total | P4: Best cost | Q4: Best type | R4: Best unit price | S4: Best total | T4: Allowance type | U4: Note
A5: 1 | B5: BALLPARK — Addition > Phase 1 - General Requirements > Permits | C5: Permit | D5: General Requirements | E5: Lump Sum | F5: {Addition Permit Fee} | G5: =p_Addition_Permit_Fee -> 200 | H5: 1 | I5: O | J5: =H5*INDEX(MarkupVals,MATCH(I5,MarkupCodes,0)) -> 1.45 | K5: =G5*J5 -> 290 | L5: 1 | M5: O | N5: =L5*INDEX(MarkupVals,MATCH(M5,MarkupCodes,0)) -> 1.45 | O5: =G5*N5 -> 290 | P5: 1 | Q5: O | R5: =P5*INDEX(MarkupVals,MATCH(Q5,MarkupCodes,0)) -> 1.45 | S5: =G5*R5 -> 290 | U5: Quantity is the permit fee in dollars at $1.00 each, so it can follow the jurisdiction: the estimator enters the fee from the permit table on the Rates tab as the Permit Fee parameter. Marked up like other costs.
A6: 2 | B6: BALLPARK — Addition > Phase 1 - General Requirements > Project/Site Management | C6: Project Management (C) | D6: Project Management | E6: Hours | F6: 6 + {Addition Living Space}*ceil({Addition Width}*{Addition Depth}*{Addition Stories}/30) | G6: =6 + p_Addition_Living_Space*ROUNDUP(p_Addition_Width*p_Addition_Depth*p_Addition_Stories/30,0) -> 17 | H6: =LaborCost -> 55 | I6: L | J6: =H6*INDEX(MarkupVals,MATCH(I6,MarkupCodes,0)) -> 100 | K6: =G6*J6 -> 1700 | L6: =LaborCost -> 55 | M6: L | N6: =L6*INDEX(MarkupVals,MATCH(M6,MarkupCodes,0)) -> 100 | O6: =G6*N6 -> 1700 | P6: =LaborCost -> 55 | Q6: L | R6: =P6*INDEX(MarkupVals,MATCH(Q6,MarkupCodes,0)) -> 100 | S6: =G6*R6 -> 1700
A7: 3 | B7: BALLPARK — Addition > Phase 1 - General Requirements > Site Preparation | C7: Site Prep Material | D7: Site Construction | E7: Each | F7: 1 | G7: =1 -> 1 | H7: 150 | I7: M | J7: =H7*INDEX(MarkupVals,MATCH(I7,MarkupCodes,0)) -> 217.5 | K7: =G7*J7 -> 217.5 | L7: 150 | M7: M | N7: =L7*INDEX(MarkupVals,MATCH(M7,MarkupCodes,0)) -> 217.5 | O7: =G7*N7 -> 217.5 | P7: 150 | Q7: M | R7: =P7*INDEX(MarkupVals,MATCH(Q7,MarkupCodes,0)) -> 217.5 | S7: =G7*R7 -> 217.5
A8: 4 | B8: BALLPARK — Addition > Phase 1 - General Requirements > Site Preparation | C8: Site Prep Labor | D8: Site Prep/Clean Up | E8: Hours | F8: 4 + ceil({Addition Width}*{Addition Depth}*{Addition Stories}/200) | G8: =4 + ROUNDUP(p_Addition_Width*p_Addition_Depth*p_Addition_Stories/200,0) -> 6 | H8: =LaborCost -> 55 | I8: L | J8: =H8*INDEX(MarkupVals,MATCH(I8,MarkupCodes,0)) -> 100 | K8: =G8*J8 -> 600 | L8: =LaborCost -> 55 | M8: L | N8: =L8*INDEX(MarkupVals,MATCH(M8,MarkupCodes,0)) -> 100 | O8: =G8*N8 -> 600 | P8: =LaborCost -> 55 | Q8: L | R8: =P8*INDEX(MarkupVals,MATCH(Q8,MarkupCodes,0)) -> 100 | S8: =G8*R8 -> 600
A9: 5 | B9: BALLPARK — Addition > Phase 1 - General Requirements > Site Preparation | C9: Rentals & Delivery | D9: General Requirements | E9: Each | F9: 1 + ceil({Addition Width}*{Addition Depth}*{Addition Stories}/400) + 3*{Addition Living Space} | G9: =1 + ROUNDUP(p_Addition_Width*p_Addition_Depth*p_Addition_Stories/400,0) + 3*p_Addition_Living_Space -> 5 | H9: 300 | I9: O | J9: =H9*INDEX(MarkupVals,MATCH(I9,MarkupCodes,0)) -> 435 | K9: =G9*J9 -> 2175 | L9: 300 | M9: O | N9: =L9*INDEX(MarkupVals,MATCH(M9,MarkupCodes,0)) -> 435 | O9: =G9*N9 -> 2175 | P9: 300 | Q9: O | R9: =P9*INDEX(MarkupVals,MATCH(Q9,MarkupCodes,0)) -> 435 | S9: =G9*R9 -> 2175 | U9: P-Pod, dumpster buggy and deliveries. A finished room runs longer and carries about three more rental weeks.
A10: 6 | B10: BALLPARK — Addition > Phase 1 - General Requirements > Demolition | C10: Demolition | D10: Demolition | E10: Hours | F10: 4*(1 - {Addition Detached}) + ceil({Addition Structure Removed}/3) + 8*{Addition Wall Openings} | G10: =4*(1 - p_Addition_Detached) + ROUNDUP(p_Addition_Structure_Removed/3,0) + 8*p_Addition_Wall_Openings -> 12 | H10: =LaborCost -> 55 | I10: L | J10: =H10*INDEX(MarkupVals,MATCH(I10,MarkupCodes,0)) -> 100 | K10: =G10*J10 -> 1200 | L10: =LaborCost -> 55 | M10: L | N10: =L10*INDEX(MarkupVals,MATCH(M10,MarkupCodes,0)) -> 100 | O10: =G10*N10 -> 1200 | P10: =LaborCost -> 55 | Q10: L | R10: =P10*INDEX(MarkupVals,MATCH(Q10,MarkupCodes,0)) -> 100 | S10: =G10*R10 -> 1200 | U10: 4 h to open up an attached addition, 1 h per 3 SF of structure torn down, and 8 h per opening cut into the house.
A11: 7 | B11: BALLPARK — Addition > Phase 1 - General Requirements > Site Clean Up | C11: Hauling & Disposal | D11: Hauling & Disposal (Direct) | E11: Each | F11: {Addition Dumpster Loads} | G11: =p_Addition_Dumpster_Loads -> 1 | H11: 250 | I11: L | J11: 450 | K11: =G11*J11 -> 450 | L11: 250 | M11: L | N11: 450 | O11: =G11*N11 -> 450 | P11: 250 | Q11: L | R11: 450 | S11: =G11*R11 -> 450 | U11: Uses DB's existing catalog item: $250 cost / $450 price per load.
A12: 8 | B12: BALLPARK — Addition > Phase 1 - General Requirements > Site Clean Up | C12: Final Clean | D12: Site Prep/Clean Up | E12: Hours | F12: 2 + 2*{Addition Living Space} | G12: =2 + 2*p_Addition_Living_Space -> 4 | H12: =LaborCost -> 55 | I12: L | J12: =H12*INDEX(MarkupVals,MATCH(I12,MarkupCodes,0)) -> 100 | K12: =G12*J12 -> 400 | L12: =LaborCost -> 55 | M12: L | N12: =L12*INDEX(MarkupVals,MATCH(M12,MarkupCodes,0)) -> 100 | O12: =G12*N12 -> 400 | P12: =LaborCost -> 55 | Q12: L | R12: =P12*INDEX(MarkupVals,MATCH(Q12,MarkupCodes,0)) -> 100 | S12: =G12*R12 -> 400
A13: 9 | B13: BALLPARK — Addition > Phase 1 - General Requirements > Travel | C13: Travel | D13: Travel Related Costs | E13: Hours | F13: ceil(({Addition Service Zone} - 1)*({Addition Service Zone} + 2)/8*((6 + {Addition Living Space}*ceil({Addition Width}*{Addition Depth}*{Addition Stories}/30)) + (4 + ceil({Addition Width}*{Addition Depth}*{Addition Stories}/200)) + (4*(1 - {Addition Detached}) + ceil({Addition Structure Removed}/3) + 8*{Addition Wall Openings}) + (2 + 2*{Addition Living Space}) + (16*{Addition Site Excavation}) + (3*{Addition Piers}) + (ceil({Addition Width}*{Addition Depth}*{Addition Stories}/6) + 8*{Addition Wall Openings} + 8*{Addition Roof Tie-In}) + (ceil(({Addition Width} + 2*{Addition Depth} + {Addition Detached}*{Addition Width})*{Addition Wall Height}*{Addition Stories}*1.15/100) + {Addition Extra Siding Squares}) + (ceil(2.5*{Addition Windows})) + (8*{Addition Exterior Doors} + 8*{Addition Patio Doors} + 3*{Addition Interior Doors}) + (9*{Addition Plumbing Fixtures}) + ({Addition Electrical}*(8 + ceil({Addition Width}*{Addition Depth}*{Addition Stories}/16))) + ({Addition Drywall}*ceil({Addition Width}*{Addition Depth}*{Addition Stories}/12)) + ({Addition Drywall}*ceil({Addition Width}*{Addition Depth}*{Addition Stories}/15)) + ({Addition Living Space}*ceil({Addition Width}*{Addition Depth}*{Addition Stories}/25)) + ({Addition Living Space}*(4 + ceil(({Addition Width} + 2*{Addition Depth} + {Addition Detached}*{Addition Width})*{Addition Stories}/8) + {Addition Windows} + {Addition Exterior Doors} + {Addition Patio Doors})))/8) | G13: =ROUNDUP((p_Addition_Service_Zone - 1)*(p_Addition_Service_Zone + 2)/8*((6 + p_Addition_Living_Space*ROUNDUP(p_Addition_Width*p_Addition_Depth*p_Addition_Stories/30,0)) + (4 + ROUNDUP(p_Addition_Width*p_Addition_Depth*p_Addition_Stories/200,0)) + (4*(1 - p_Addition_Detached) + ROUNDUP(p_Addition_Structure_Removed/3,0) + 8*p_Addition_Wall_Openings) + (2 + 2*p_Addition_Living_Space) + (16*p_Addition_Site_Excavation) + (3*p_Addition_Piers) + (ROUNDUP(p_Addition_Width*p_Addition_Depth*p_Addition_Stories/6,0) + 8*p_Addition_Wall_Openings + 8*p_Addition_Roof_Tie_In) + (ROUNDUP((p_Addition_Width + 2*p_Addition_Depth + p_Addition_Detached*p_Addition_Width)*p_Addition_Wall_Height*p_Addition_Stories*1.15/100,0) + p_Addition_Extra_Siding_Squares) + (ROUNDUP(2.5*p_Addition_Windows,0)) + (8*p_Addition_Exterior_Doors + 8*p_Addition_Patio_Doors + 3*p_Addition_Interior_Doors) + (9*p_Addition_Plumbing_Fixtures) + (p_Addition_Electrical*(8 + ROUNDUP(p_Addition_Width*p_Addition_Depth*p_Addition_Stories/16,0))) + (p_Addition_Drywall*ROUNDUP(p_Addition_Width*p_Addition_Depth*p_Addition_Stories/12,0)) + (p_Addition_Drywall*ROUNDUP(p_Addition_Width*p_Addition_Depth*p_Addition_Stories/15,0)) + (p_Addition_Living_Space*ROUNDUP(p_Addition_Width*p_Addition_Depth*p_Addition_Stories/25,0)) + (p_Addition_Living_Space*(4 + ROUNDUP((p_Addition_Width + 2*p_Addition_Depth + p_Addition_Detached*p_Addition_Width)*p_Addition_Stories/8,0) + p_Addition_Windows + p_Addition_Exterior_Doors + p_Addition_Patio_Doors)))/8,0) -> 0 | H13: =LaborCost -> 55 | I13: L | J13: =H13*INDEX(MarkupVals,MATCH(I13,MarkupCodes,0)) -> 100 | K13: =G13*J13 -> 0 | L13: =LaborCost -> 55 | M13: L | N13: =L13*INDEX(MarkupVals,MATCH(M13,MarkupCodes,0)) -> 100 | O13: =G13*N13 -> 0 | P13: =LaborCost -> 55 | Q13: L | R13: =P13*INDEX(MarkupVals,MATCH(Q13,MarkupCodes,0)) -> 100 | S13: =G13*R13 -> 0 | U13: Travel by the job's Service Zone (JobTread sets it from the address): hours = person-days x (z-1)(z+2)/8, which is 0, 0.5 and 1.25 h per person-day for Zones 1, 2 and 3. Those are DB's own Service Call zone charges ($85 / $115 / $155 cost) turned into travel time. Extended (over 50 mi) is quoted by hand; zone 4 gives 2.25 h per person-day as a floor.
A14: 10 | B14: BALLPARK — Addition > Phase 1 - General Requirements > Utilities | C14: Utility - Electric | D14: Utility Connection | E14: Linear Feet | F14: {Addition Utility Trench} | G14: =p_Addition_Utility_Trench -> 0 | H14: 12 | I14: O | J14: =H14*INDEX(MarkupVals,MATCH(I14,MarkupCodes,0)) -> 17.4 | K14: =G14*J14 -> 0 | L14: 12 | M14: O | N14: =L14*INDEX(MarkupVals,MATCH(M14,MarkupCodes,0)) -> 17.4 | O14: =G14*N14 -> 0 | P14: 12 | Q14: O | R14: =P14*INDEX(MarkupVals,MATCH(Q14,MarkupCodes,0)) -> 17.4 | S14: =G14*R14 -> 0 | U14: Catalog item, per foot of trench to a detached building. Matched both garage estimates.
A15: 11 | B15: BALLPARK — Addition > Phase 2 - Foundation & Framing > Site Work | C15: Excavation & Grading | D15: Excavation | E15: Hours | F15: 16*{Addition Site Excavation} | G15: =16*p_Addition_Site_Excavation -> 0 | H15: =LaborCost -> 55 | I15: L | J15: =H15*INDEX(MarkupVals,MATCH(I15,MarkupCodes,0)) -> 100 | K15: =G15*J15 -> 0 | L15: =LaborCost -> 55 | M15: L | N15: =L15*INDEX(MarkupVals,MATCH(M15,MarkupCodes,0)) -> 100 | O15: =G15*N15 -> 0 | P15: =LaborCost -> 55 | Q15: L | R15: =P15*INDEX(MarkupVals,MATCH(Q15,MarkupCodes,0)) -> 100 | S15: =G15*R15 -> 0 | U15: Only when DB digs or grades. Most concrete subs include excavation in their price.
A16: 12 | B16: BALLPARK — Addition > Phase 2 - Foundation & Framing > Site Work | C16: Rental - Mini Excavator | D16: Excavation | E16: Day | F16: 2*{Addition Site Excavation} | G16: =2*p_Addition_Site_Excavation -> 0 | H16: 195 | I16: O | J16: =H16*INDEX(MarkupVals,MATCH(I16,MarkupCodes,0)) -> 282.75 | K16: =G16*J16 -> 0 | L16: 195 | M16: O | N16: =L16*INDEX(MarkupVals,MATCH(M16,MarkupCodes,0)) -> 282.75 | O16: =G16*N16 -> 0 | P16: 195 | Q16: O | R16: =P16*INDEX(MarkupVals,MATCH(Q16,MarkupCodes,0)) -> 282.75 | S16: =G16*R16 -> 0
A17: 13 | B17: BALLPARK — Addition > Phase 2 - Foundation & Framing > Foundation | C17: Concrete Foundation - Crawl | D17: Concrete | E17: Square Foot | F17: {Addition Crawl Space}*{Addition Width}*{Addition Depth} | G17: =p_Addition_Crawl_Space*p_Addition_Width*p_Addition_Depth -> 320 | H17: 18.07 | I17: M | J17: =H17*INDEX(MarkupVals,MATCH(I17,MarkupCodes,0)) -> 26.2015 | K17: =G17*J17 -> 8384.48 | L17: 18.07 | M17: M | N17: =L17*INDEX(MarkupVals,MATCH(M17,MarkupCodes,0)) -> 26.2015 | O17: =G17*N17 -> 8384.48 | P17: 18.07 | Q17: M | R17: =P17*INDEX(MarkupVals,MATCH(Q17,MarkupCodes,0)) -> 26.2015 | S17: =G17*R17 -> 8384.48 | U17: DB catalog item. Matched 258410's crawl-space sub to within 1% ($26.30 against $26.20 price per SF).
A18: 14 | B18: BALLPARK — Addition > Phase 2 - Foundation & Framing > Foundation | C18: Concrete Foundation - 6" Stem | D18: Concrete | E18: Square Foot | F18: {Addition Slab}*{Addition Width}*{Addition Depth} | G18: =p_Addition_Slab*p_Addition_Width*p_Addition_Depth -> 0 | H18: 21 | I18: M | J18: =H18*INDEX(MarkupVals,MATCH(I18,MarkupCodes,0)) -> 30.45 | K18: =G18*J18 -> 0 | L18: 21 | M18: M | N18: =L18*INDEX(MarkupVals,MATCH(M18,MarkupCodes,0)) -> 30.45 | O18: =G18*N18 -> 0 | P18: 21 | Q18: M | R18: =P18*INDEX(MarkupVals,MATCH(Q18,MarkupCodes,0)) -> 30.45 | S18: =G18*R18 -> 0 | U18: DB catalog item: 3 ft footing, 6 in stem wall, 4 in slab. The 14x24 garage's sub ran $45.60 per SF; small slabs cost more per foot.
A19: 15 | B19: BALLPARK — Addition > Phase 2 - Foundation & Framing > Foundation | C19: Concrete Foundation - Basement | D19: Concrete | E19: Square Foot | F19: {Addition Basement}*{Addition Width}*{Addition Depth} | G19: =p_Addition_Basement*p_Addition_Width*p_Addition_Depth -> 0 | H19: 33 | I19: M | J19: =H19*INDEX(MarkupVals,MATCH(I19,MarkupCodes,0)) -> 47.85 | K19: =G19*J19 -> 0 | L19: 33 | M19: M | N19: =L19*INDEX(MarkupVals,MATCH(M19,MarkupCodes,0)) -> 47.85 | O19: =G19*N19 -> 0 | P19: 33 | Q19: M | R19: =P19*INDEX(MarkupVals,MATCH(Q19,MarkupCodes,0)) -> 47.85 | S19: =G19*R19 -> 0 | U19: DB catalog item. No basement addition in the data; this line is untested.
A20: 16 | B20: BALLPARK — Addition > Phase 2 - Foundation & Framing > Foundation | C20: Concrete Piers | D20: Concrete | E20: Each | F20: {Addition Piers} | G20: =p_Addition_Piers -> 0 | H20: 500 | I20: M | J20: =H20*INDEX(MarkupVals,MATCH(I20,MarkupCodes,0)) -> 725 | K20: =G20*J20 -> 0 | L20: 500 | M20: M | N20: =L20*INDEX(MarkupVals,MATCH(M20,MarkupCodes,0)) -> 725 | O20: =G20*N20 -> 0 | P20: 500 | Q20: M | R20: =P20*INDEX(MarkupVals,MATCH(Q20,MarkupCodes,0)) -> 725 | S20: =G20*R20 -> 0 | U20: Per pier or post, with the labor line beside it. From the porch-type addition on three piers.
A21: 17 | B21: BALLPARK — Addition > Phase 2 - Foundation & Framing > Foundation | C21: Pier Labor | D21: Concrete | E21: Hours | F21: 3*{Addition Piers} | G21: =3*p_Addition_Piers -> 0 | H21: =LaborCost -> 55 | I21: L | J21: =H21*INDEX(MarkupVals,MATCH(I21,MarkupCodes,0)) -> 100 | K21: =G21*J21 -> 0 | L21: =LaborCost -> 55 | M21: L | N21: =L21*INDEX(MarkupVals,MATCH(M21,MarkupCodes,0)) -> 100 | O21: =G21*N21 -> 0 | P21: =LaborCost -> 55 | Q21: L | R21: =P21*INDEX(MarkupVals,MATCH(Q21,MarkupCodes,0)) -> 100 | S21: =G21*R21 -> 0
A22: 18 | B22: BALLPARK — Addition > Phase 2 - Foundation & Framing > Framing | C22: Framing/Sheathing Materials | D22: Woods & Plastics | E22: Square Foot | F22: {Addition Width}*{Addition Depth}*{Addition Stories} | G22: =p_Addition_Width*p_Addition_Depth*p_Addition_Stories -> 320 | H22: 22.5 | I22: M | J22: =H22*INDEX(MarkupVals,MATCH(I22,MarkupCodes,0)) -> 32.625 | K22: =G22*J22 -> 10440 | L22: 22.5 | M22: M | N22: =L22*INDEX(MarkupVals,MATCH(M22,MarkupCodes,0)) -> 32.625 | O22: =G22*N22 -> 10440 | P22: 22.5 | Q22: M | R22: =P22*INDEX(MarkupVals,MATCH(Q22,MarkupCodes,0)) -> 32.625 | S22: =G22*R22 -> 10440 | U22: DB catalog item, updated to $22.50 cost per SF of floor (from $17.65) to match DB's two most recent lumber quotes ($22.8 and $22.4). Check it against the latest quote every quarter.
A23: 19 | B23: BALLPARK — Addition > Phase 2 - Foundation & Framing > Framing | C23: Header & Opening Material | D23: Woods & Plastics | E23: Each | F23: {Addition Wall Openings} | G23: =p_Addition_Wall_Openings -> 1 | H23: 400 | I23: M | J23: =H23*INDEX(MarkupVals,MATCH(I23,MarkupCodes,0)) -> 580 | K23: =G23*J23 -> 580 | L23: 400 | M23: M | N23: =L23*INDEX(MarkupVals,MATCH(M23,MarkupCodes,0)) -> 580 | O23: =G23*N23 -> 580 | P23: 400 | Q23: M | R23: =P23*INDEX(MarkupVals,MATCH(Q23,MarkupCodes,0)) -> 580 | S23: =G23*R23 -> 580
A24: 20 | B24: BALLPARK — Addition > Phase 2 - Foundation & Framing > Framing | C24: Framing/Sheathing Labor | D24: Framing/Sheeting | E24: Hours | F24: ceil({Addition Width}*{Addition Depth}*{Addition Stories}/6) + 8*{Addition Wall Openings} + 8*{Addition Roof Tie-In} | G24: =ROUNDUP(p_Addition_Width*p_Addition_Depth*p_Addition_Stories/6,0) + 8*p_Addition_Wall_Openings + 8*p_Addition_Roof_Tie_In -> 70 | H24: =LaborCost -> 55 | I24: L | J24: =H24*INDEX(MarkupVals,MATCH(I24,MarkupCodes,0)) -> 100 | K24: =G24*J24 -> 7000 | L24: =LaborCost -> 55 | M24: L | N24: =L24*INDEX(MarkupVals,MATCH(M24,MarkupCodes,0)) -> 100 | O24: =G24*N24 -> 7000 | P24: =LaborCost -> 55 | Q24: L | R24: =P24*INDEX(MarkupVals,MATCH(Q24,MarkupCodes,0)) -> 100 | S24: =G24*R24 -> 7000 | U24: 1 h per 6 SF of floor, plus 8 h per wall opening and per tie-in level. Matched DB's hours on 258410 (84 against 86) and 258551 (60 against 62). A framing sub costs about the same: $19 per SF price.
A25: 21 | B25: BALLPARK — Addition > Phase 3 - Exterior & Rough-In > Roofing | C25: Gutters & Downspouts | D25: Roofing | E25: Linear Feet | F25: {Addition Width} + {Addition Depth} + 20 | G25: =p_Addition_Width + p_Addition_Depth + 20 -> 56 | H25: 8.25 | I25: M | J25: =H25*INDEX(MarkupVals,MATCH(I25,MarkupCodes,0)) -> 11.9625 | K25: =G25*J25 -> 669.9 | L25: 8.25 | M25: M | N25: =L25*INDEX(MarkupVals,MATCH(M25,MarkupCodes,0)) -> 11.9625 | O25: =G25*N25 -> 669.9 | P25: 8.25 | Q25: M | R25: =P25*INDEX(MarkupVals,MATCH(Q25,MarkupCodes,0)) -> 11.9625 | S25: =G25*R25 -> 669.9 | U25: Width + depth + 20 ft of downspout. Matched the 25-8197 and 260109 gutter lines within 10%.
A26: 22 | B26: BALLPARK — Addition > Phase 3 - Exterior & Rough-In > Roofing | C26: Gutter Labor | D26: Roofing | E26: Linear Feet | F26: {Addition Width} + {Addition Depth} + 20 | G26: =p_Addition_Width + p_Addition_Depth + 20 -> 56 | H26: 3.5 | I26: U | J26: =H26*INDEX(MarkupVals,MATCH(I26,MarkupCodes,0)) -> 5.075 | K26: =G26*J26 -> 284.2 | L26: 3.5 | M26: U | N26: =L26*INDEX(MarkupVals,MATCH(M26,MarkupCodes,0)) -> 5.075 | O26: =G26*N26 -> 284.2 | P26: 3.5 | Q26: U | R26: =P26*INDEX(MarkupVals,MATCH(Q26,MarkupCodes,0)) -> 5.075 | S26: =G26*R26 -> 284.2
A27: 23 | B27: BALLPARK — Addition > Phase 3 - Exterior & Rough-In > Siding | C27: Soffit & Fascia Material | D27: Siding | E27: Linear Feet | F27: ({Addition Width} + 2*{Addition Depth} + {Addition Detached}*{Addition Width}) | G27: =(p_Addition_Width + 2*p_Addition_Depth + p_Addition_Detached*p_Addition_Width) -> 52 | H27: 8 | I27: M | J27: =H27*INDEX(MarkupVals,MATCH(I27,MarkupCodes,0)) -> 11.6 | K27: =G27*J27 -> 603.2 | L27: 8 | M27: M | N27: =L27*INDEX(MarkupVals,MATCH(M27,MarkupCodes,0)) -> 11.6 | O27: =G27*N27 -> 603.2 | P27: 8 | Q27: M | R27: =P27*INDEX(MarkupVals,MATCH(Q27,MarkupCodes,0)) -> 11.6 | S27: =G27*R27 -> 603.2
A28: 24 | B28: BALLPARK — Addition > Phase 3 - Exterior & Rough-In > Siding | C28: Fascia and Soffit Install | D28: Siding | E28: Linear Feet | F28: ({Addition Width} + 2*{Addition Depth} + {Addition Detached}*{Addition Width}) | G28: =(p_Addition_Width + 2*p_Addition_Depth + p_Addition_Detached*p_Addition_Width) -> 52 | H28: 4.5 | I28: S | J28: =H28*INDEX(MarkupVals,MATCH(I28,MarkupCodes,0)) -> 5.85 | K28: =G28*J28 -> 304.2 | L28: 4.5 | M28: S | N28: =L28*INDEX(MarkupVals,MATCH(M28,MarkupCodes,0)) -> 5.85 | O28: =G28*N28 -> 304.2 | P28: 4.5 | Q28: S | R28: =P28*INDEX(MarkupVals,MATCH(Q28,MarkupCodes,0)) -> 5.85 | S28: =G28*R28 -> 304.2
A29: 25 | B29: BALLPARK — Addition > Phase 3 - Exterior & Rough-In > Siding | C29: House Wrap Labor | D29: Siding | E29: Hours | F29: ceil(({Addition Width} + 2*{Addition Depth} + {Addition Detached}*{Addition Width})*{Addition Wall Height}*{Addition Stories}*1.15/100) + {Addition Extra Siding Squares} | G29: =ROUNDUP((p_Addition_Width + 2*p_Addition_Depth + p_Addition_Detached*p_Addition_Width)*p_Addition_Wall_Height*p_Addition_Stories*1.15/100,0) + p_Addition_Extra_Siding_Squares -> 5 | H29: =LaborCost -> 55 | I29: L | J29: =H29*INDEX(MarkupVals,MATCH(I29,MarkupCodes,0)) -> 100 | K29: =G29*J29 -> 500 | L29: =LaborCost -> 55 | M29: L | N29: =L29*INDEX(MarkupVals,MATCH(M29,MarkupCodes,0)) -> 100 | O29: =G29*N29 -> 500 | P29: =LaborCost -> 55 | Q29: L | R29: =P29*INDEX(MarkupVals,MATCH(Q29,MarkupCodes,0)) -> 100 | S29: =G29*R29 -> 500 | U29: One hour per square, as on 25-8197, 258410 and 260109.
A30: 26 | B30: BALLPARK — Addition > Phase 3 - Exterior & Rough-In > Siding | C30: Siding Labor | D30: Siding | E30: Square | F30: ceil(({Addition Width} + 2*{Addition Depth} + {Addition Detached}*{Addition Width})*{Addition Wall Height}*{Addition Stories}*1.15/100) + {Addition Extra Siding Squares} | G30: =ROUNDUP((p_Addition_Width + 2*p_Addition_Depth + p_Addition_Detached*p_Addition_Width)*p_Addition_Wall_Height*p_Addition_Stories*1.15/100,0) + p_Addition_Extra_Siding_Squares -> 5 | H30: 160 | I30: U | J30: =H30*INDEX(MarkupVals,MATCH(I30,MarkupCodes,0)) -> 232 | K30: =G30*J30 -> 1160 | L30: 160 | M30: U | N30: =L30*INDEX(MarkupVals,MATCH(M30,MarkupCodes,0)) -> 232 | O30: =G30*N30 -> 1160 | P30: 160 | Q30: U | R30: =P30*INDEX(MarkupVals,MATCH(Q30,MarkupCodes,0)) -> 232 | S30: =G30*R30 -> 1160 | U30: Catalog $160 per square ($232 price). One garage estimate charged $326 per square.
A31: 27 | B31: BALLPARK — Addition > Phase 3 - Exterior & Rough-In > Siding | C31: Siding Labor for Flashing | D31: Siding | E31: Each | F31: 2*(1 - {Addition Detached}) | G31: =2*(1 - p_Addition_Detached) -> 2 | H31: 150 | I31: U | J31: =H31*INDEX(MarkupVals,MATCH(I31,MarkupCodes,0)) -> 217.5 | K31: =G31*J31 -> 435 | L31: 150 | M31: U | N31: =L31*INDEX(MarkupVals,MATCH(M31,MarkupCodes,0)) -> 217.5 | O31: =G31*N31 -> 435 | P31: 150 | Q31: U | R31: =P31*INDEX(MarkupVals,MATCH(Q31,MarkupCodes,0)) -> 217.5 | S31: =G31*R31 -> 435
A32: 28 | B32: BALLPARK — Addition > Phase 3 - Exterior & Rough-In > Windows & Doors | C32: Window Labor | D32: Windows | E32: Hours | F32: ceil(2.5*{Addition Windows}) | G32: =ROUNDUP(2.5*p_Addition_Windows,0) -> 10 | H32: =LaborCost -> 55 | I32: L | J32: =H32*INDEX(MarkupVals,MATCH(I32,MarkupCodes,0)) -> 100 | K32: =G32*J32 -> 1000 | L32: =LaborCost -> 55 | M32: L | N32: =L32*INDEX(MarkupVals,MATCH(M32,MarkupCodes,0)) -> 100 | O32: =G32*N32 -> 1000 | P32: =LaborCost -> 55 | Q32: L | R32: =P32*INDEX(MarkupVals,MATCH(Q32,MarkupCodes,0)) -> 100 | S32: =G32*R32 -> 1000
A33: 29 | B33: BALLPARK — Addition > Phase 3 - Exterior & Rough-In > Windows & Doors | C33: Exterior Door & Lockset | D33: Doors | E33: Each | F33: {Addition Exterior Doors} | G33: =p_Addition_Exterior_Doors -> 0 | H33: 1230 | I33: M | J33: =H33*INDEX(MarkupVals,MATCH(I33,MarkupCodes,0)) -> 1783.5 | K33: =G33*J33 -> 0 | L33: 1230 | M33: M | N33: =L33*INDEX(MarkupVals,MATCH(M33,MarkupCodes,0)) -> 1783.5 | O33: =G33*N33 -> 0 | P33: 1230 | Q33: M | R33: =P33*INDEX(MarkupVals,MATCH(Q33,MarkupCodes,0)) -> 1783.5 | S33: =G33*R33 -> 0 | U33: Same as the kitchen template. 258410's entry door and lockset were $1,834 price.
A34: 30 | B34: BALLPARK — Addition > Phase 3 - Exterior & Rough-In > Windows & Doors | C34: Garage Door | D34: Doors | E34: Each | F34: {Addition Garage Doors} | G34: =p_Addition_Garage_Doors -> 0 | H34: 1300 | I34: S | J34: =H34*INDEX(MarkupVals,MATCH(I34,MarkupCodes,0)) -> 1690 | K34: =G34*J34 -> 0 | L34: 1300 | M34: S | N34: =L34*INDEX(MarkupVals,MATCH(M34,MarkupCodes,0)) -> 1690 | O34: =G34*N34 -> 0 | P34: 1300 | Q34: S | R34: =P34*INDEX(MarkupVals,MATCH(Q34,MarkupCodes,0)) -> 1690 | S34: =G34*R34 -> 0 | U34: Catalog Garage Door, installed by the sub. Neither garage estimate priced its overhead doors; if the owner supplies them, keep the line at $0 and name it (by owner).
A35: 31 | B35: BALLPARK — Addition > Phase 3 - Exterior & Rough-In > Windows & Doors | C35: Garage Door Wrapping | D35: Doors | E35: Each | F35: {Addition Garage Doors} | G35: =p_Addition_Garage_Doors -> 0 | H35: 105 | I35: U | J35: =H35*INDEX(MarkupVals,MATCH(I35,MarkupCodes,0)) -> 152.25 | K35: =G35*J35 -> 0 | L35: 105 | M35: U | N35: =L35*INDEX(MarkupVals,MATCH(M35,MarkupCodes,0)) -> 152.25 | O35: =G35*N35 -> 0 | P35: 105 | Q35: U | R35: =P35*INDEX(MarkupVals,MATCH(Q35,MarkupCodes,0)) -> 152.25 | S35: =G35*R35 -> 0
A36: 32 | B36: BALLPARK — Addition > Phase 3 - Exterior & Rough-In > Windows & Doors | C36: Door Labor | D36: Doors | E36: Hours | F36: 8*{Addition Exterior Doors} + 8*{Addition Patio Doors} + 3*{Addition Interior Doors} | G36: =8*p_Addition_Exterior_Doors + 8*p_Addition_Patio_Doors + 3*p_Addition_Interior_Doors -> 8 | H36: =LaborCost -> 55 | I36: L | J36: =H36*INDEX(MarkupVals,MATCH(I36,MarkupCodes,0)) -> 100 | K36: =G36*J36 -> 800 | L36: =LaborCost -> 55 | M36: L | N36: =L36*INDEX(MarkupVals,MATCH(M36,MarkupCodes,0)) -> 100 | O36: =G36*N36 -> 800 | P36: =LaborCost -> 55 | Q36: L | R36: =P36*INDEX(MarkupVals,MATCH(Q36,MarkupCodes,0)) -> 100 | S36: =G36*R36 -> 800
A37: 33 | B37: BALLPARK — Addition > Phase 3 - Exterior & Rough-In > Plumbing & HVAC | C37: Plumbing Materials | D37: Mechanical (Plumbing & HVAC) | E37: Each | F37: {Addition Plumbing Fixtures} | G37: =p_Addition_Plumbing_Fixtures -> 0 | H37: 250 | I37: M | J37: =H37*INDEX(MarkupVals,MATCH(I37,MarkupCodes,0)) -> 362.5 | K37: =G37*J37 -> 0 | L37: 250 | M37: M | N37: =L37*INDEX(MarkupVals,MATCH(M37,MarkupCodes,0)) -> 362.5 | O37: =G37*N37 -> 0 | P37: 250 | Q37: M | R37: =P37*INDEX(MarkupVals,MATCH(Q37,MarkupCodes,0)) -> 362.5 | S37: =G37*R37 -> 0 | U37: Rough-in only: $250 and 9 h per fixture, from 258410's bathroom (37 h and $914 for four fixtures). The fixtures and finishes come from the bathroom or kitchen template.
A38: 34 | B38: BALLPARK — Addition > Phase 3 - Exterior & Rough-In > Plumbing & HVAC | C38: Plumbing Labor | D38: Mechanical (Plumbing & HVAC) | E38: Hours | F38: 9*{Addition Plumbing Fixtures} | G38: =9*p_Addition_Plumbing_Fixtures -> 0 | H38: =LaborCost -> 55 | I38: L | J38: =H38*INDEX(MarkupVals,MATCH(I38,MarkupCodes,0)) -> 100 | K38: =G38*J38 -> 0 | L38: =LaborCost -> 55 | M38: L | N38: =L38*INDEX(MarkupVals,MATCH(M38,MarkupCodes,0)) -> 100 | O38: =G38*N38 -> 0 | P38: =LaborCost -> 55 | Q38: L | R38: =P38*INDEX(MarkupVals,MATCH(Q38,MarkupCodes,0)) -> 100 | S38: =G38*R38 -> 0
A39: 35 | B39: BALLPARK — Addition > Phase 3 - Exterior & Rough-In > Plumbing & HVAC | C39: HVAC Extension (sub) | D39: Mechanical (Plumbing & HVAC) | E39: Lump Sum | F39: {Addition HVAC Extend} | G39: =p_Addition_HVAC_Extend -> 1 | H39: 1310 | I39: S | J39: =H39*INDEX(MarkupVals,MATCH(I39,MarkupCodes,0)) -> 1703 | K39: =G39*J39 -> 1703 | L39: 1310 | M39: S | N39: =L39*INDEX(MarkupVals,MATCH(M39,MarkupCodes,0)) -> 1703 | O39: =G39*N39 -> 1703 | P39: 1310 | Q39: S | R39: =P39*INDEX(MarkupVals,MATCH(Q39,MarkupCodes,0)) -> 1703 | S39: =G39*R39 -> 1703 | U39: Matches the $1,703 duct extension on 258684.
A40: 36 | B40: BALLPARK — Addition > Phase 3 - Exterior & Rough-In > Plumbing & HVAC | C40: HVAC New Unit (sub) | D40: Mechanical (Plumbing & HVAC) | E40: Lump Sum | F40: {Addition HVAC New Unit} | G40: =p_Addition_HVAC_New_Unit -> 0 | H40: 7500 | I40: S | J40: =H40*INDEX(MarkupVals,MATCH(I40,MarkupCodes,0)) -> 9750 | K40: =G40*J40 -> 0 | L40: 7500 | M40: S | N40: =L40*INDEX(MarkupVals,MATCH(M40,MarkupCodes,0)) -> 9750 | O40: =G40*N40 -> 0 | P40: 7500 | Q40: S | R40: =P40*INDEX(MarkupVals,MATCH(Q40,MarkupCodes,0)) -> 9750 | S40: =G40*R40 -> 0 | U40: Median of DB's four addition HVAC subs, $7,979 to $13,000 price.
A41: 37 | B41: BALLPARK — Addition > Phase 3 - Exterior & Rough-In > Electrical | C41: Electrical Materials | D41: Electrical | E41: Square Foot | F41: {Addition Electrical}*{Addition Width}*{Addition Depth}*{Addition Stories} | G41: =p_Addition_Electrical*p_Addition_Width*p_Addition_Depth*p_Addition_Stories -> 320 | H41: 2.61 | I41: M | J41: =H41*INDEX(MarkupVals,MATCH(I41,MarkupCodes,0)) -> 3.7845 | K41: =G41*J41 -> 1211.04 | L41: 2.61 | M41: M | N41: =L41*INDEX(MarkupVals,MATCH(M41,MarkupCodes,0)) -> 3.7845 | O41: =G41*N41 -> 1211.04 | P41: 2.61 | Q41: M | R41: =P41*INDEX(MarkupVals,MATCH(Q41,MarkupCodes,0)) -> 3.7845 | S41: =G41*R41 -> 1211.04 | U41: DB catalog: $2.61 cost per SF of floor, the same as the kitchen template.
...

Sheet Parameters
A1: JobTread job parameters used by the formulas
A2: Verified 27 Sep 2026: formula variables are job parameters (job.parameters), the same mechanism DB's roofing formulas use. Names must match exactly. Every name starts with 'Addition ' so a job carrying more than one ballpark template never shares a parameter between rooms.
A4: JobTread parameter | B4: Type | C4: Default | D4: How to measure / count | E4: Used by (line items)
A5: Addition Width | B5: Number | C5: 20 | D5: Feet along the house wall (for a detached building, the front wall) | E5: Concrete Foundation - 6" Stem, Concrete Foundation - Basement, Concrete Foundation - Crawl, Drywall Board - Mat, Drywall Labor, Drywall Mud - Mat, Electrical Labor, Electrical Materials, Fascia and Soffit Install, Flooring - Misc. Material, Flooring Labor, Flooring Material, Framing/Sheathing Labor, Framing/Sheathing Materials, Gutter Labor, Gutters & Downspouts, House Wrap Labor, Insulation - Sub, Paint, Paint Labor, Project Management (C), Rentals & Delivery, Roofing Install, Roofing Material, Siding Labor, Siding Material, Site Prep Labor, Soffit & Fascia Material, Travel, Trim - Baseboard, Trim Labor
A6: Addition Depth | B6: Number | C6: 16 | D6: Feet out from the house | E6: Concrete Foundation - 6" Stem, Concrete Foundation - Basement, Concrete Foundation - Crawl, Drywall Board - Mat, Drywall Labor, Drywall Mud - Mat, Electrical Labor, Electrical Materials, Fascia and Soffit Install, Flooring - Misc. Material, Flooring Labor, Flooring Material, Framing/Sheathing Labor, Framing/Sheathing Materials, Gutter Labor, Gutters & Downspouts, House Wrap Labor, Insulation - Sub, Paint, Paint Labor, Project Management (C), Rentals & Delivery, Roofing Install, Roofing Material, Siding Labor, Siding Material, Site Prep Labor, Soffit & Fascia Material, Travel, Trim - Baseboard, Trim Labor
A7: Addition Stories | B7: Number | C7: 1 | D7: Finished floors on the new footprint: 1 or 2 | E7: Drywall Board - Mat, Drywall Labor, Drywall Mud - Mat, Electrical Labor, Electrical Materials, Flooring - Misc. Material, Flooring Labor, Flooring Material, Framing/Sheathing Labor, Framing/Sheathing Materials, House Wrap Labor, Insulation - Sub, Paint, Paint Labor, Project Management (C), Rentals & Delivery, Siding Labor, Siding Material, Site Prep Labor, Travel, Trim - Baseboard, Trim Labor
A8: Addition Wall Height | B8: Number | C8: 8 | D8: Wall height in feet per storey (8 for most rooms; 9–10 for garages) | E8: House Wrap Labor, Siding Labor, Siding Material, Travel
A9: Addition Detached | B9: Number | C9: 0 | D9: 1 = stand-alone building such as a garage (four new walls, no tie-in); 0 = attached | E9: Demolition, Fascia and Soffit Install, House Wrap Labor, Siding Labor, Siding Labor for Flashing, Siding Material, Soffit & Fascia Material, Travel, Trim - Baseboard, Trim Labor
A10: Addition Crawl Space | B10: Number | C10: 0 | D10: 1 = new crawl-space foundation. Set exactly one foundation to 1. | E10: Concrete Foundation - Crawl
A11: Addition Slab | B11: Number | C11: 0 | D11: 1 = footed slab with a 6-inch stem wall (garages, slab rooms) | E11: Concrete Foundation - 6" Stem
A12: Addition Basement | B12: Number | C12: 0 | D12: 1 = full basement under the addition | E12: Concrete Foundation - Basement
A13: Addition Piers | B13: Number | C13: 0 | D13: Posts or piers, for a porch-type addition on piers (count). 0 for any other foundation. | E13: Concrete Piers, Pier Labor, Travel
A14: Addition Site Excavation | B14: Number | C14: 0 | D14: 1 = DB digs, grades or trenches (tight access, slope, drainage). 0 = the concrete sub's price covers it. | E14: Excavation & Grading, Rental - Mini Excavator, Travel
A15: Addition Roof Tie-In | B15: Number | C15: 1 | D15: 0 = none (detached); 1 = simple shed or gable against the house; 2 = cross-gable or valley | E15: Framing/Sheathing Labor, Roofing Install, Roofing Material, Travel
A16: Addition Electrical | B16: Number | C16: 1 | D16: 1 = wired: outlets, lights, switches. 0 = shell only. | E16: Electrical Labor, Electrical Materials, Travel
... A32: Addition Service Zone | B32: Number | C32: 1 | D32: Service Zone from the job in JobTread: 1 (within ~15 mi), 2 (~15-30 mi), 3 (~30-50 mi). Zone 1 adds no travel. Extended (over 50 mi) is quoted by hand: enter 4 as a floor and flag it. | E32: Travel
A33: Addition Contingency Rate | B33: Number | C33: 10 | D33: Contingency as a % of the tier total, set by the estimator: 10 for additions and structural work
A34: Addition Permit Fee | B34: Number | C34: 200 | D34: Permit fee DB pays the city or township, in dollars (cost), from the permit table on the Rates tab. The estimator sets it from the job address. | E34: Permit

Sheet Rates
A1: Markup by cost type
A3: Cost type code | B3: Cost type | C3: Price ÷ cost | D3: Note
A4: L | B4: Labor | C4: =C12/C11 -> 1.8181818 | D4: DB catalog labor: $55 cost / $100 price per hour (a 45% margin).
A5: M | B5: Materials | C5: 1.45 | D5: DB catalog materials: ×1.45 with zero variance across the catalog (field notes §9).
A6: S | B6: Subcontractor | C6: 1.3 | D6: Countertop, tile and flooring subs in DB's estimates were marked up ×1.30.
A7: O | B7: Other | C7: 1.45 | D7: Permits and misc. fees: ×1.45.
A8: U | B8: Labor, per unit | C8: 1.45 | D8: Labor the catalog prices per square or foot (siding, roofing, gutters). JobTread cost type Labor, marked up ×1.45 like the catalog.
A9: C | B9: Contingency | C9: 1 | D9: Its own line, carried at cost so it can be reported and credited. JobTread cost type Other with the markup set to 0, cost code Contingency.
A11: Labor cost per hour | C11: 55 | D11: Used as the unit cost of every labor line on the Template tab.
A12: Labor price per hour | C12: 100
A14: Budget range accuracy (±) | C14: 0.2 | D14: Additions are quoted at ±20% and always go on to the Design & Pricing Agreement.
A16: Permit fees by jurisdiction | D16: DB's vendor bills for permits, last 6 months. Enter the job's fee as the Permit Fee parameter.
A17: Jurisdiction | D17: Fee DB pays
A18: Village of Convoy | D18: $10
A19: City of Van Wert | D19: $20 for the first $10K of project cost, plus $2 per additional $1K (paid $20–$122, average $36)
A20: City of Lima | D20: $63
A21: Lucas County | D21: $75.75
A22: Union Township | D22: $100
A23: Pleasant Township Trustees | D23: $300
A24: Deitemeyer Brothers internal | D24: $32–$40, average $36
A26: Travel by service zone | D26: Travel by the job's Service Zone (JobTread sets it from the address): hours = person-days x (z-1)(z+2)/8, which is 0, 0.5 and 1.25 h per person-day for Zones 1, 2 and 3. Those are DB's own Service Call zone charges ($85 / $115 / $155 cost) turned into travel time. Extended (over 50 mi) is quoted by hand; zone 4 gives 2.25 h per person-day as a floor.
A27: Service Zone | B27: Enter | C27: Hours per person-day
A28: Zone 1 (within ~15 mi) | B28: 1 | C28: 0
A29: Zone 2 (~15–30 mi) | B29: 2 | C29: 0.5
A30: Zone 3 (~30–50 mi) | B30: 3 | C30: 1.25
A31: Extended (over 50 mi): quote by hand | B31: 4 | C31: 2.25

Sheet Calibration
A1: Checks against DB's addition estimates since the move to JobTread
A2: Like for like: actual = estimate total less work another template or an add-on prices (listed below); model = template total less lines the estimate carried at $0. Intake was rebuilt from each estimate's own lines, so this is not an out-of-sample test.
A3: 258684 is shown but not counted: a tear-down and rebuild with deck work, stone and a PVC roof deck.
A5: Totals
A6: Job | B6: Status | C6: What it is | D6: Floor SF | E6: Actual (same scope) | F6: Model at its tier | G6: Error | H6: Actual $/SF | I6: Model Good | J6: Model Better | K6: Model Best | L6: |Error| | M6: Addition Width | N6: Addition Depth | O6: Addition Stories | P6: Addition Wall Height | Q6: Addition Detached | R6: Addition Crawl Space | S6: Addition Slab | T6: Addition Basement | U6: Addition Piers | V6: Addition Site Excavation | W6: Addition Roof Tie-In | X6: Addition Electrical | Y6: Addition Drywall | Z6: Addition Living Space | AA6: Addition Windows | AB6: Addition Exterior Doors | AC6: Addition Patio Doors | AD6: Addition Garage Doors | AE6: Addition Interior Doors | AF6: Addition Wall Openings | AG6: Addition Plumbing Fixtures | AH6: Addition HVAC Extend | AI6: Addition HVAC New Unit | AJ6: Addition Extra Siding Squares | AK6: Addition Structure Removed | AL6: Addition Utility Trench | AM6: Addition Dumpster Loads | AN6: Addition Service Zone | AO6: Addition Permit Fee
A7: 258410 | B7: approved | C7: Finished 420 SF room on a crawl, with a bathroom; re-sided the house to match | D7: 420 | E7: 136051.6 | F7: 122283.57 | G7: =(F7-E7)/E7 -> -0.10119712 | H7: =E7/D7 -> 323.93238 | I7: 118760.07 | J7: 125234.32 | K7: 139428.37 | L7: =ABS(G7) -> 0.10119712 | M7: 20 | N7: 21 | O7: 1 | P7: 8 | Q7: 0 | R7: 1 | S7: 0 | T7: 0 | U7: 0 | V7: 1 | W7: 1 | X7: 1 | Y7: 1 | Z7: 1 | AA7: 5 | AB7: 1 | AC7: 0 | AD7: 0 | AE7: 4 | AF7: 1 | AG7: 4 | AH7: 0 | AI7: 1 | AJ7: 21 | AK7: 0 | AL7: 0 | AM7: 1 | AN7: 1 | AO7: 200
A8: 25-8197 | B8: approved | C8: 795 SF shell on a crawl, framed and dried in; customer finishes the inside | D8: 792 | E8: 91096.38 | F8: 85071.31 | G8: =(F8-E8)/E8 -> -0.066139511 | H8: =E8/D8 -> 115.02068 | I8: 85071.31 | J8: 87942.31 | K8: 93961.26 | L8: =ABS(G8) -> 0.066139511 | M8: 22 | N8: 36 | O8: 1 | P8: 8 | Q8: 0 | R8: 1 | S8: 0 | T8: 0 | U8: 0 | V8: 0 | W8: 1 | X8: 0 | Y8: 0 | Z8: 0 | AA8: 0 | AB8: 0 | AC8: 1 | AD8: 0 | AE8: 0 | AF8: 1 | AG8: 0 | AH8: 0 | AI8: 0 | AJ8: 0 | AK8: 0 | AL8: 0 | AM8: 1 | AN8: 1 | AO8: 200
A9: 261040 | B9: approved | C9: 286 SF porch-type room on piers; wired, not insulated | D9: 286 | E9: 30650.72 | F9: 34328.83 | G9: =(F9-E9)/E9 -> 0.12000077 | H9: =E9/D9 -> 107.17035 | I9: 34328.83 | J9: 35416.33 | K9: 38443.93 | L9: =ABS(G9) -> 0.12000077 | M9: 13 | N9: 22 | O9: 1 | P9: 8 | Q9: 0 | R9: 0 | S9: 0 | T9: 0 | U9: 3 | V9: 0 | W9: 1 | X9: 1 | Y9: 0 | Z9: 0 | AA9: 0 | AB9: 0 | AC9: 0 | AD9: 0 | AE9: 0 | AF9: 0 | AG9: 0 | AH9: 0 | AI9: 0 | AJ9: 0 | AK9: 0 | AL9: 0 | AM9: 1 | AN9: 1 | AO9: 200
A10: 261094 | B10: pending | C10: Detached 24x24 garage on a footed slab, drywalled, heated | D10: 576 | E10: 80138.97 | F10: 81459.59 | G10: =(F10-E10)/E10 -> 0.016479124 | H10: =E10/D10 -> 139.13016 | I10: 81459.59 | J10: 81459.59 | K10: 81459.59 | L10: =ABS(G10) -> 0.016479124 | M10: 24 | N10: 24 | O10: 1 | P10: 8 | Q10: 1 | R10: 0 | S10: 1 | T10: 0 | U10: 0 | V10: 1 | W10: 0 | X10: 1 | Y10: 1 | Z10: 0 | AA10: 0 | AB10: 1 | AC10: 0 | AD10: 2 | AE10: 0 | AF10: 0 | AG10: 0 | AH10: 0 | AI10: 1 | AJ10: 0 | AK10: 0 | AL10: 80 | AM10: 1 | AN10: 1 | AO10: 200
A11: 260109 | B11: approved | C11: Detached 14x24 garage on a footed slab, drywalled | D11: 336 | E11: 55878.86 | F11: 55682.09 | G11: =(F11-E11)/E11 -> -0.0035213675 | H11: =E11/D11 -> 166.30613 | I11: 55682.09 | J11: 57501.84 | K11: 61692.34 | L11: =ABS(G11) -> 0.0035213675 | M11: 14 | N11: 24 | O11: 1 | P11: 8 | Q11: 1 | R11: 0 | S11: 1 | T11: 0 | U11: 0 | V11: 0 | W11: 0 | X11: 1 | Y11: 1 | Z11: 0 | AA11: 2 | AB11: 1 | AC11: 0 | AD11: 0 | AE11: 0 | AF11: 0 | AG11: 0 | AH11: 0 | AI11: 0 | AJ11: 0 | AK11: 0 | AL11: 50 | AM11: 1 | AN11: 1 | AO11: 200
A12: 246466 | B12: approved | C12: About 360 SF sunroom on a crawl, with a stone-coated steel roof | D12: 360 | E12: 115817.78 | F12: 105311.82 | G12: =(F12-E12)/E12 -> -0.090711115 | H12: =E12/D12 -> 321.71606 | I12: 98372.12 | J12: 104643.37 | K12: 116534.82 | L12: =ABS(G12) -> 0.090711115 | M12: 18 | N12: 20 | O12: 1 | P12: 8 | Q12: 0 | R12: 1 | S12: 0 | T12: 0 | U12: 0 | V12: 0 | W12: 1 | X12: 1 | Y12: 1 | Z12: 1 | AA12: 10 | AB12: 1 | AC12: 1 | AD12: 0 | AE12: 0 | AF12: 1 | AG12: 0 | AH12: 0 | AI12: 1 | AJ12: 0 | AK12: 130 | AL12: 0 | AM12: 1 | AN12: 1 | AO12: 200
A13: 258551 | B13: denied | C13: 273 SF kitchen addition on a crawl | D13: 273 | E13: 68589.48 | F13: 77062.19 | G13: =(F13-E13)/E13 -> 0.12352784 | H13: =E13/D13 -> 251.24352 | I13: 77062.19 | J13: 78939.21 | K13: 83876.46 | L13: =ABS(G13) -> 0.12352784 | M13: 21 | N13: 13 | O13: 1 | P13: 8 | Q13: 0 | R13: 1 | S13: 0 | T13: 0 | U13: 0 | V13: 0 | W13: 1 | X13: 1 | Y13: 1 | Z13: 1 | AA13: 1 | AB13: 2 | AC13: 0 | AD13: 0 | AE13: 0 | AF13: 1 | AG13: 2 | AH13: 0 | AI13: 1 | AJ13: 0 | AK13: 114 | AL13: 0 | AM13: 1 | AN13: 1 | AO13: 200
A14: 258684 | B14: approved | C14: Tear-down and rebuild of a 333 SF sunroom, with a PVC roof deck and deck work | D14: 336 | E14: 174713.8 | F14: 102279.98 | G14: =(F14-E14)/E14 -> -0.41458557 | H14: =E14/D14 -> 519.98155 | I14: 86505.43 | J14: 91941.48 | K14: 102279.98 | L14: =ABS(G14) -> 0.41458557 | M14: 21 | N14: 16 | O14: 1 | P14: 8 | Q14: 0 | R14: 1 | S14: 0 | T14: 0 | U14: 0 | V14: 0 | W14: 1 | X14: 1 | Y14: 1 | Z14: 1 | AA14: 8 | AB14: 0 | AC14: 1 | AD14: 0 | AE14: 0 | AF14: 0 | AG14: 0 | AH14: 1 | AI14: 0 | AJ14: 0 | AK14: 333 | AL14: 0 | AM14: 2 | AN14: 1 | AO14: 200
A16: Median absolute error (counted estimates) | E16: =MEDIAN(L7:L13) -> 0.090711115
A17: Median error (bias) | E17: =MEDIAN(G7:G13) -> -0.0035213675
A18: Counted estimates within ±15% | E18: =SUMPRODUCT(--(L7:L13<=0.15))&" of "&COUNT(L7:L13) -> 7 of 7
A20: Block by block (model against actual, same scope)
A21: Large offsets cancel in the totals. '-' = under $500 in the estimate, or left unpriced by it.
A22: Block | D22: 258410 | E22: 25-8197 | F22: 261040 | G22: 261094 | H22: 260109 | I22: 246466 | J22: 258551 | K22: 258684
A23: Foundation & site | D23: -12% | E23: -27% | F23: -8% | G23: -6% | H23: -33% | I23: +3% | J23: +98% | K23: -68%
A24: Framing | D24: +27% | E24: -2% | F24: +69% | G24: -7% | H24: -14% | I24: -9% | J24: +39% | K24: -36%
A25: Roofing & gutters | D25: -44% | E25: -2% | F25: +3% | G25: - | H25: +80% | I25: -68% | J25: +19% | K25: -88%
A26: Siding, soffit & fascia | D26: -28% | E26: +59% | F26: -27% | G26: - | H26: +20% | I26: +155% | J26: +48% | K26: -30%
A27: Windows & doors | D27: +5% | E27: -42% | F27: - | G27: - | H27: +195% | I27: -2% | J27: +56% | K27: +117%
A28: Insulation, drywall, paint, floor, trim | D28: +6% | E28: - | F28: - | G28: +87% | H28: +65% | I28: +31% | J28: -10% | K28: -2%
A29: Electrical, plumbing & HVAC | D29: -19% | E29: - | F29: -8% | G29: +21% | H29: -12% | I29: -8% | J29: -13% | K29: -3%
A30: Demolition & general | D30: -13% | E30: +66% | F30: +1% | G30: -36% | H30: -1% | I30: -15% | J30: +0% | K30: -31%
A32: Left out of the actual (priced by another template or an add-on)
A33: 258410 | C33: Cabinetry $5,703; Closet Organization $378; Shower/Tub $2,552; Specialites $8,173; Bathroom fixtures and trim (toilet, faucets, shower trim) $2,907
A34: 25-8197 | C34: Design $7,000
A35: 246466 | C35: Design $3,079; Composite deck, 196 SF $8,501
A36: 258551 | C36: Cabinetry $53,777; Design $5,000
A37: 258684 | C37: Deck $11,340
A38: Left out of the model (the estimate carried these at $0)
A39: 260109 | C39: Insulation - Sub
A40: 261094 | C40: Insulation - Sub, Siding Material, Siding Labor, House Wrap Labor, Siding Labor for Flashing, Roofing Material, Roofing Install, Gutters & Downspouts, Gutter Labor, Soffit & Fascia Material, Fascia and Soffit Install, Garage Door, Garage Door Wrapping, Exterior Door & Lockset, Door Labor
A42: Rebuilt inputs to note: 246466 and 258551 carry the SF torn down that matches their demolition hours; 258410 carries 21 extra siding squares from its house-wrap line (28 squares against 7 for the addition).
A43: 260109's framing package bundled its roof, siding and window materials, so its blocks shift while its total holds.
A44: Not used: 260820 (porch repair), 261340 (garage conversion), 261265 (pole building), 261377 (siding only), 261089 and 260056 (remodels). Kay Oss jobs are test jobs.
